Workbook

Sheet Estimacion
A1: Estimacion de esfuerzo por sprints | J1: Estimacion por tipo de esfuerzo
A2: Planificación | B2: Simple | C2: Muy facil | D2: Facil | E2: Normal | F2: Dificil | G2: Muy dificil | H2: Horas | K2: Simple | L2: Muy facil | M2: Facil | N2: Normal | O2: Dificil | P2: Muy dificil
A3: Historias de usuarios | D3: 1 | H3: =(B3*$K$3)+(C3*$L$3)+(D3*$M$3)+(E3*$N$3)+(F3*$O$3)+(G3*$P$3) -> 16 | J3: Horas | K3: 4 | L3: 8 | M3: 16 | N3: 24 | O3: 32 | P3: 48
A4: Propuesta de solución | D4: 1 | H4: =(B4*$K$3)+(C4*$L$3)+(D4*$M$3)+(E4*$N$3)+(F4*$O$3)+(G4*$P$3) -> 16
A5: Diagramas | F5: 1 | H5: =(B5*$K$3)+(C5*$L$3)+(D5*$M$3)+(E5*$N$3)+(F5*$O$3)+(G5*$P$3) -> 32 | J5: Total esfuerzo
A6: Planificación de Sprints | D6: 1 | H6: =(B6*$K$3)+(C6*$L$3)+(D6*$M$3)+(E6*$N$3)+(F6*$O$3)+(G6*$P$3) -> 16 | J6: Horas | K6: Dias | L6: Semanas | M6: Meses
A7: Reuniones | G7: 1 | H7: =(B7*$K$3)+(C7*$L$3)+(D7*$M$3)+(E7*$N$3)+(F7*$O$3)+(G7*$P$3) -> 48 | J7: =SUM(H3:H7,H10:H21,H24:H30,H33:H35,H38:H43,H45:H49,H52:H58,) -> 952 | K7: =J7/8 -> 119 | L7: =ROUND(J7/45,0) -> 21 | M7: =ROUND(J7/180,0) -> 5 | R7: =J7 -> 952
A8: Total Esfuerzo | B8: =SUM(B3:B7) -> 0 | C8: =SUM(C3:C7) -> 0 | D8: =SUM(D3:D7) -> 3 | E8: =SUM(E3:E7) -> 0 | F8: =SUM(F3:F7) -> 1 | G8: =SUM(G3:G7) -> 1 | H8: =SUM(H3:H7) -> 128
A9: Sprint 1 | B9: Simple | C9: Muy facil | D9: Facil | E9: Normal | F9: Dificil | G9: Muy dificil | H9: Horas
A10: Configuración de la BD | C10: 1 | H10: =(B10*$K$3)+(C10*$L$3)+(D10*$M$3)+(E10*$N$3)+(F10*$O$3)+(G10*$P$3) -> 8 | J10: Agenda & Recursos
A11: Preparación de entorno Backend | C11: 1 | H11: =(B11*$K$3)+(C11*$L$3)+(D11*$M$3)+(E11*$N$3)+(F11*$O$3)+(G11*$P$3) -> 8 | J11: Horas | K11: Recurso 1 | L11: Recurso 2 | M11: Recurso 3
A12: Preparación de entorno Frontend | C12: 1 | H12: =(B12*$K$3)+(C12*$L$3)+(D12*$M$3)+(E12*$N$3)+(F12*$O$3)+(G12*$P$3) -> 8 | J12: Dias | K12: =J7/8 -> 119 | L12: =ROUND(K12/2,0) -> 60 | M12: =ROUND(K12/3,0) -> 40
A13: Creación de contenedor para BD (Docker) | D13: 1 | H13: =(B13*$K$3)+(C13*$L$3)+(D13*$M$3)+(E13*$N$3)+(F13*$O$3)+(G13*$P$3) -> 16 | J13: Semanas | K13: =L7 -> 21 | L13: =ROUND(K13/2,0) -> 11 | M13: =ROUND(K13/3,0) -> 7
A14: Creación de clases (Entidades BD) | E14: 1 | H14: =(B14*$K$3)+(C14*$L$3)+(D14*$M$3)+(E14*$N$3)+(F14*$O$3)+(G14*$P$3) -> 24 | J14: Meses | K14: =M7 -> 5 | L14: =ROUND(K14/2,0) -> 3 | M14: =ROUND(K14/4,0) -> 1
A15: Enrutamiento (React Router) | C15: 1 | H15: =(B15*$K$3)+(C15*$L$3)+(D15*$M$3)+(E15*$N$3)+(F15*$O$3)+(G15*$P$3) -> 8
A16: Creación de comunicados | E16: 1 | H16: =(B16*$K$3)+(C16*$L$3)+(D16*$M$3)+(E16*$N$3)+(F16*$O$3)+(G16*$P$3) -> 24
A17: Configurar roles y permisos en backend (RBAC básico) | D17: 1 | H17: =(B17*$K$3)+(C17*$L$3)+(D17*$M$3)+(E17*$N$3)+(F17*$O$3)+(G17*$P$3) -> 16
A18: Aplicar validaciones de rango y formato en mediciones | D18: 1 | H18: =(B18*$K$3)+(C18*$L$3)+(D18*$M$3)+(E18*$N$3)+(F18*$O$3)+(G18*$P$3) -> 16
A19: Diseñar interfaz base para ingreso y visualización de mediciones | E19: 1 | H19: =(B19*$K$3)+(C19*$L$3)+(D19*$M$3)+(E19*$N$3)+(F19*$O$3)+(G19*$P$3) -> 24
A20: Implementar sistema de login y registro de usuarios | E20: 1 | H20: =(B20*$K$3)+(C20*$L$3)+(D20*$M$3)+(E20*$N$3)+(F20*$O$3)+(G20*$P$3) -> 24
A21: Ajustes visuales y pruebas de integración con API | D21: 1 | H21: =(B21*$K$3)+(C21*$L$3)+(D21*$M$3)+(E21*$N$3)+(F21*$O$3)+(G21*$P$3) -> 16
A22: Total Esfuerzo | B22: =SUM(B10:B16) -> 0 | C22: =SUM(C10:C17) -> 4 | D22: =SUM(D10:D21) -> 4 | E22: =SUM(E10:E21) -> 4 | F22: =SUM(F10:F16) -> 0 | G22: =SUM(G10:G16) -> 0 | H22: =SUM(H10:H21) -> 192
A23: Sprint 2 | B23: Simple | C23: Muy facil | D23: Facil | E23: Normal | F23: Dificil | G23: Muy dificil | H23: Horas
A24: Crear endpoints REST para configuración de rangos personalizados. | C24: 1 | H24: =(B24*$K$3)+(C24*$L$3)+(D24*$M$3)+(E24*$N$3)+(F24*$O$3)+(G24*$P$3) -> 8
A25: Diseñar interfaz en frontend para que el médico visualice y edite rangos | D25: 1 | H25: =(B25*$K$3)+(C25*$L$3)+(D25*$M$3)+(E25*$N$3)+(F25*$O$3)+(G25*$P$3) -> 16
A26: Integrar comparación automática de mediciones con rangos configurados. | E26: 1 | H26: =(B26*$K$3)+(C26*$L$3)+(D26*$M$3)+(E26*$N$3)+(F26*$O$3)+(G26*$P$3) -> 24
A27: Agregar control de versión automática al modificar un rango de paciente | E27: 1 | H27: =(B27*$K$3)+(C27*$L$3)+(D27*$M$3)+(E27*$N$3)+(F27*$O$3)+(G27*$P$3) -> 24
A28: Registrar cada cambio de rango en el historial | D28: 1 | H28: =(B28*$K$3)+(C28*$L$3)+(D28*$M$3)+(E28*$N$3)+(F28*$O$3)+(G28*$P$3) -> 16
A29: Implementar lógica de generación automática de alerta | E29: 1 | H29: =(B29*$K$3)+(C29*$L$3)+(D29*$M$3)+(E29*$N$3)+(F29*$O$3)+(G29*$P$3) -> 24
A30: Notificación visual de la alerta en frontend médico | D30: 1 | H30: =(B30*$K$3)+(C30*$L$3)+(D30*$M$3)+(E30*$N$3)+(F30*$O$3)+(G30*$P$3) -> 16
A31: Total Esfuerzo | B31: =SUM(B24:B30) -> 0 | C31: =SUM(C24:C30) -> 1 | D31: =SUM(D24:D30) -> 3 | E31: =SUM(E24:E30) -> 3 | F31: =SUM(F24:F30) -> 0 | G31: =SUM(G24:G30) -> 0 | H31: =SUM(H24:H30) -> 128
A32: Sprint 3 | B32: Simple | C32: Muy facil | D32: Facil | E32: Normal | F32: Dificil | G32: Muy dificil | H32: Horas
A33: Diseñar e implementar el dashboard de priorización de pacientes por nivel de riesgo, incluyendo la lógica de cálculo y ordenamiento. | F33: 1 | H33: =(B33*$K$3)+(C33*$L$3)+(D33*$M$3)+(E33*$N$3)+(F33*$O$3)+(G33*$P$3) -> 32
A34: Implementar filtros por fecha, paciente y severidad de alerta en el dashboard, permitiendo el análisis detallado de casos específicos. | E34: 1 | H34: =(B34*$K$3)+(C34*$L$3)+(D34*$M$3)+(E34*$N$3)+(F34*$O$3)+(G34*$P$3) -> 24
A35: Desarrollar las gráficas de tendencia de las mediciones de cada paciente en los últimos 30 días e integrarlas a la vista clínica. | F35: 1 | H35: =(B35*$K$3)+(C35*$L$3)+(D35*$M$3)+(E35*$N$3)+(F35*$O$3)+(G35*$P$3) -> 32
A36: Total Esfuerzo | B36: =SUM(B33:B35) -> 0 | C36: =SUM(C33:C35) -> 0 | D36: =SUM(D33:D35) -> 0 | E36: =SUM(E33:E35) -> 1 | F36: =SUM(F33:F35) -> 2 | G36: =SUM(G33:G35) -> 0 | H36: =SUM(H33:H35) -> 88
A37: Sprint 4 | B37: Simple | C37: Muy facil | D37: Facil | E37: Normal | F37: Dificil | G37: Muy dificil | H37: Horas
A38: Implementar la notificación al cuidador cuando el paciente presente una alerta fuera de rango, considerando su vínculo con el paciente. | D38: 1 | H38: =(B38*$K$3)+(C38*$L$3)+(D38*$M$3)+(E38*$N$3)+(F38*$O$3)+(G38*$P$3) -> 16
A39: Desarrollar la configuración de preferencias de alertas del cuidador (tipos de alertas que desea recibir) e incorporarlas en el flujo. | D39: 1 | H39: =(B39*$K$3)+(C39*$L$3)+(D39*$M$3)+(E39*$N$3)+(F39*$O$3)+(G39*$P$3) -> 16
A40: Implementar el envío de notificaciones vía correo electrónico para las alertas generadas por el sistema, incluyendo registro básico de envíos. | D40: 1 | H40: =(B40*$K$3)+(C40*$L$3)+(D40*$M$3)+(E40*$N$3)+(F40*$O$3)+(G40*$P$3) -> 16
...

Sheet Costos
B2: Costos del proyecto
B3: Tiempo/Recurso | C3: 1 | D3: 2 | E3: 3 | H3: Sueldo bruto | I3: 964000
B4: Dias | C4: =Estimacion!K12 -> 119 | D4: =Estimacion!L12 -> 60 | E4: =Estimacion!M12 -> 40 | H4: Costo por hora | I4: =(I3/31)/8 -> 3887.0968
B5: Semanas | C5: =Estimacion!K13 -> 21 | D5: =Estimacion!L13 -> 11 | E5: =Estimacion!M13 -> 7
B6: Meses | C6: =Estimacion!K14 -> 5 | D6: =Estimacion!L14 -> 3 | E6: =Estimacion!M14 -> 1
B7: Total | C7: =I4*Estimacion!R7 -> 3700516.1 | D7: =C7/2 -> 1850258.1 | E7: =C7/3 -> 1233505.4
